<?xml version="1.0"?>

<robot name="simpleton" xmlns:xacro="http://www.ros.org/wiki/xacro">



	<!-- Base link --> 
	<link name="footprint" />

	<!-- Chassis --> 
  <joint name="base_joint" type="fixed">
    <parent link="footprint"/>
    <child link="chassis"/>
  </joint>

  <link name="chassis">
    <collision>
      <origin xyz="0 0 0.3" rpy="0 0 0"/>
      <geometry>
			<box size="1 0.2 0.1"/>
      </geometry>
    </collision>

    <visual>
      <origin xyz="0 0 0.3" rpy="0 0 0"/>
      <geometry>
			<box size="1 0.2 0.1"/>
      </geometry>
      <material name="orange"/>
    </visual>

		<inertial>
		  <mass value="1"/>
			<origin xyz="0 0 0.3" rpy="0 0 0"/>
		  <inertia ixx="0.4" ixy="0.1" ixz="0.1" iyy="0.4" iyz="0.1" izz="0.2"/>
		</inertial>
  </link>

	<gazebo reference="chassis">
		<!--Stiffness --> 
		<kp>1000000.0</kp>
		<!--Dampening--> 
		<kd>0.1</kd>
		<dampingFactor>0</dampingFactor>
		<material>Gazebo/White</material>
		<selfCollide>true</selfCollide>
		<turnGravityOff>false</turnGravityOff>
		<mu1 value="0.0"/>
    <mu2 value="0.0"/>
    <fdir1 value="0 0 0"/>
	</gazebo>

	<!-- Left Wheel - Start -->
	<link name="left_wheel">
    <collision>
      <origin xyz="0 0 0" rpy="0 1.5708 1.5708" />
      <geometry>
       <cylinder length="0.1" radius="0.3"/>
      </geometry>
		</collision>

	  <visual>
	    <origin xyz="0 0 0" rpy="0 1.5708 1.5708" />
	    <geometry>
	     <cylinder length="0.1" radius="0.3"/>
	    </geometry>
	    <material name="black"/>
	  </visual>

	  <inertial>
	    <origin xyz="0 0 0" rpy="0 1.5708 1.5708" />
	    <mass value="0.2"/>
	    <cylinder_inertia m="0.2" r="0.3" h="0.1"/>
			<inertia ixx="0.4" ixy="0.1" ixz="0.1" iyy="0.4" iyz="0.1" izz="0.2"/>
	  </inertial>
 	</link>

  <gazebo reference="left_wheel">
    <mu1 value="2.0"/>
    <mu2 value="2.0"/>
    <kp  value="10000000.0" />
    <kd  value="1.0" />
    <fdir1 value="0 1 0"/>
    <material>Gazebo/Blue</material>
  </gazebo>


 	<joint name="left_wheel_hinge" type="continuous">
    <parent link="chassis"/>
    <child link="left_wheel"/>
    <origin xyz="0.1 -0.15 0.3" rpy="0 0 0" /> 
    <axis xyz="0 1 0" rpy="0 0 0" />
    <limit effort="100" velocity="100"/>
    <!--<joint_properties damping="0.0" friction="5.0"/>-->
    <dynamics damping="0.0" friction="0.0"/>
  </joint>

  <transmission name="left_trans">
    <type>transmission_interface/SimpleTransmission</type>
    <joint name="left_wheel_hinge">
        <hardwareInterface>EffortJointInterface</hardwareInterface>
    </joint>
    <actuator name="leftMotor">
    <hardwareInterface>hardwareInterface/EffortJointInterface</hardwareInterface>
    <mechanicalReduction>10</mechanicalReduction>
    </actuator>
  </transmission>

	<!-- Left Wheel - End --> 

	<!-- Right Wheel - Start -->
	<link name="right_wheel">
  <collision>
    <origin xyz="0 0 0" rpy="0 1.5708 1.5708" />
    <geometry>
     <cylinder length="0.1" radius="0.3"/>
    </geometry>
  </collision>

  <visual>
    <origin xyz="0 0 0" rpy="0 1.5708 1.5708" />
    <geometry>
     <cylinder length="0.1" radius="0.3"/>
    </geometry>
    <material name="black"/>
  </visual>

  <inertial>
    <origin xyz="0 0 0" rpy="0 1.5708 1.5708" />
    <mass value="0.2"/>
    <cylinder_inertia m="0.2" r="0.3" h="0.1"/>
		<inertia ixx="0.4" ixy="0.1" ixz="0.1" iyy="0.4" iyz="0.1" izz="0.2"/>
  </inertial>
 </link>

  <gazebo reference="right_wheel">
    <mu1 value="2.0"/>
    <mu2 value="2.0"/>
    <kp  value="10000000.0" />
    <kd  value="1.0" />
    <fdir1 value="0 1 0"/>
    <material>Gazebo/Blue</material>
  </gazebo>


 	<joint name="right_wheel_hinge" type="continuous">
    <parent link="chassis"/>
    <child link="right_wheel"/>
    <origin xyz="0.1 0.15 0.3" rpy="0 0 0" /> 
    <axis xyz="0 1 0" rpy="0 0 0" />
    <limit effort="100" velocity="100"/>
    <!--<joint_properties damping="0.0" friction="5.0"/>-->
    <dynamics damping="0.0" friction="0.0"/>
  </joint>

  <transmission name="right_trans">
    <type>transmission_interface/SimpleTransmission</type>
    <joint name="right_wheel_hinge">
        <hardwareInterface>EffortJointInterface</hardwareInterface>
    </joint>
    <actuator name="rightMotor">
    <hardwareInterface>hardwareInterface/EffortJointInterface</hardwareInterface>
    <mechanicalReduction>10</mechanicalReduction>
    </actuator>
  </transmission>

	<!-- Right Wheel - End --> 



	<gazebo>
		<plugin name="differential_drive_controller" filename="libgazebo_ros_diff_drive.so">
		  <legacyMode>false</legacyMode>
		  <alwaysOn>true</alwaysOn>
		  <updateRate>100</updateRate>
		  <leftJoint>left_wheel_hinge</leftJoint>
		  <rightJoint>right_wheel_hinge</rightJoint>
		  <wheelSeparation>0.2</wheelSeparation>
		  <wheelDiameter>0.6</wheelDiameter>
		  <torque>2</torque>
		  <commandTopic>simpleton/cmd_vel</commandTopic>
		  <odometryTopic>simpleton/odom_diffdrive</odometryTopic>
		  <odometryFrame>odom</odometryFrame>
		  <robotBaseFrame>footprint</robotBaseFrame>
		</plugin>
	</gazebo>



</robot> 
